Workbook

Sheet TARGET MARKETING BANUA 2026
A1: KPI | B1: Q1 | E1: Q2 | H1: Q3 | K1: Q4 | N1: TOTAL
B2: JAN | C2: FEB | D2: MAR | E2: APR | F2: MEI | G2: JUN | H2: JUL | I2: AGUST | J2: SEP | K2: OKT | L2: NOP | M2: DES
A3: HONDA MOTOR | B3: 20000000 | C3: 8000000 | D3: 8000000 | E3: 15000000 | F3: 15000000 | G3: 15000000 | H3: 15000000 | I3: 15000000 | J3: 15000000 | K3: 8000000 | L3: 8000000 | M3: 8000000 | N3: =SUM(B3:M3) -> 150000000
A4: WULING | B4: 5000000 | C4: 1000000 | D4: 1000000 | E4: 5000000 | F4: 8000000 | G4: 5000000 | H4: 5000000 | I4: 10000000 | J4: 9000000 | K4: 5000000 | L4: 6000000 | M4: 5000000 | N4: =SUM(B4:M4) -> 65000000
A5: HONDA MOBIL | B5: 10000000 | C5: 1000000 | D5: 1000000 | E5: 3000000 | F5: 3000000 | G5: 5000000 | H5: 4000000 | I5: 5000000 | J5: 5000000 | K5: 3000000 | L5: 3000000 | M5: 2000000 | N5: =SUM(B5:M5) -> 45000000
A6: SUZUKI | B6: 1000000 | C6: 0 | D6: 0 | E6: 0 | F6: 1000000 | G6: 1000000 | H6: 1000000 | I6: 1000000 | J6: 0 | K6: 0 | L6: 0 | N6: =SUM(B6:M6) -> 5000000
A7: DAIHATSU | B7: 1000000 | C7: 0 | D7: 0 | E7: 0 | F7: 1000000 | G7: 1000000 | H7: 1000000 | I7: 1000000 | J7: 0 | K7: 0 | L7: 0 | N7: =SUM(B7:M7) -> 5000000
A8: MITSUBISHI | B8: 1000000 | C8: 0 | D8: 0 | E8: 0 | F8: 1000000 | G8: 1000000 | H8: 1000000 | I8: 1000000 | J8: 0 | K8: 0 | L8: 0 | N8: =SUM(B8:M8) -> 5000000
A9: MAZDA | B9: 1000000 | C9: 0 | D9: 0 | E9: 1000000 | F9: 2000000 | G9: 3000000 | H9: 3000000 | I9: 4000000 | J9: 4000000 | K9: 4000000 | L9: 4000000 | M9: 4000000 | N9: =SUM(B9:M9) -> 30000000
A10: TOYOTA | B10: 20000000 | C10: 10000000 | D10: 10000000 | E10: 10000000 | F10: 10000000 | G10: 10000000 | H10: 10000000 | I10: 10000000 | J10: 10000000 | K10: 10000000 | L10: 10000000 | M10: 5000000 | N10: =SUM(B10:M10) -> 125000000
A11: YAMAHA | B11: 5000000 | C11: 1000000 | D11: 1000000 | E11: 3000000 | F11: 5000000 | G11: 5000000 | H11: 5000000 | I11: 5000000 | J11: 5000000 | K11: 5000000 | L11: 5000000 | M11: 5000000 | N11: =SUM(B11:M11) -> 50000000
A12: SMK TBSM HONDA | B12: 0 | C12: 0 | D12: 0 | E12: 2000000 | F12: 46000000 | G12: 47000000 | H12: 45000000 | I12: 45000000 | J12: 48000000 | K12: 6000000 | L12: 5000000 | M12: 6000000 | N12: =SUM(B12:M12) -> 250000000
A13: SMK NON TBSM | B13: 0 | C13: 0 | D13: 0 | E13: 3000000 | F13: 45000000 | G13: 45000000 | H13: 47000000 | I13: 45000000 | J13: 48000000 | K13: 6000000 | L13: 5000000 | M13: 6000000 | N13: =SUM(B13:M13) -> 250000000
A14: TK | B14: 0 | C14: 0 | D14: 0 | E14: 5000000 | F14: 5000000 | G14: 5000000 | H14: 5000000 | I14: 10000000 | J14: 5000000 | K14: 5000000 | L14: 5000000 | M14: 5000000 | N14: =SUM(B14:M14) -> 50000000
A15: UMUM KAMPUS | B15: 1000000 | C15: 1000000 | D15: 1000000 | E15: 5000000 | F15: 5000000 | G15: 5000000 | H15: 5000000 | I15: 5000000 | J15: 5000000 | K15: 5000000 | L15: 5000000 | M15: 7000000 | N15: =SUM(B15:M15) -> 50000000
A16: UMUM COMPANY | B16: 20000000 | C16: 10000000 | D16: 10000000 | E16: 20000000 | F16: 22000000 | G16: 25000000 | H16: 26000000 | I16: 20000000 | J16: 22000000 | K16: 15000000 | L16: 15000000 | M16: 15000000 | N16: =SUM(B16:M16) -> 220000000
A17: UMUM KOMUNITAS | B17: 15000000 | C17: 15000000 | D17: 15000000 | E17: 15000000 | F17: 15000000 | G17: 20000000 | H17: 20000000 | I17: 20000000 | J17: 20000000 | K17: 15000000 | L17: 15000000 | M17: 15000000 | N17: =SUM(B17:M17) -> 200000000
A18: TOTAL | B18: =SUM(B2:B17) -> 100000000 | C18: =SUM(C2:C17) -> 47000000 | D18: =SUM(D2:D17) -> 47000000 | E18: =SUM(E2:E17) -> 87000000 | F18: =SUM(F2:F17) -> 184000000 | G18: =SUM(G2:G17) -> 193000000 | H18: =SUM(H2:H17) -> 193000000 | I18: =SUM(I2:I17) -> 197000000 | ... M18: =SUM(M2:M17) -> 83000000 | N18: =SUM(B18:M18) -> 1500000000
B19: 100000000 | C19: 47000000 | D19: 47000000 | E19: 87000000 | F19: 184000000 | G19: 193000000 | H19: 193000000 | I19: 197000000 | J19: 196000000 | K19: 87000000 | L19: 86000000 | M19: 83000000 | O19: its oke
O20: kan kira-kira aja kan
O21: ngga mungkin data pasti
O22: tak tunggu sampe persis 1,5 M
K23: ini narohnya dimana?
C24: artinya yang table atas di masukin jga ya? | K24: strategii | L24: kan ada slide yg tulisan strategi | M24: nah persis abis itu
C25: iyaa, tabel dulu baru grafik yg bawah
G27: MAS JUMLAHNYA LBEBIHH
G28: cek wa | L28: hah
L29: ngga taiu

Sheet DASHBOARD
B2: Marketing Banua Mitra Lestari Dashboard 2025
C6: Start Date | D6: 46113
C7: End Date | D7: 46142
C9: Sales Revenue | F9: Transaction | I9: QTY Product Terjual
C10: =sum(HELPER!H:H) -> 71550000 | F10: =COUNT(HELPER!F:F) -> 45 | I10: =SUM(HELPER!F:F) -> 797
C15: HONDA MOTOR | F15: WULING | I15: HONDA MOBIL | L15: SUZUKI
C16: =SUMIF(HELPER!$A:$A, DASHBOARD!C15, HELPER!$H:$H) -> 0 | F16: =SUMIF(HELPER!$A:$A, DASHBOARD!F15, HELPER!$H:$H) -> 0 | I16: =SUMIF(HELPER!$A:$A, DASHBOARD!I15, HELPER!$H:$H) -> 0 | L16: =SUMIF(HELPER!$A:$A, DASHBOARD!L15, HELPER!$H:$H) -> 0
Q18: TOP 5
C20: DAIHATSU | F20: MITSUBISHI | I20: MAZDA | L20: TOYOTA
C21: =SUMIF(HELPER!$A:$A, DASHBOARD!C20, HELPER!$H:$H) -> 0 | F21: =SUMIF(HELPER!$A:$A, DASHBOARD!F20, HELPER!$H:$H) -> 0 | I21: =SUMIF(HELPER!$A:$A, DASHBOARD!I20, HELPER!$H:$H) -> 0 | L21: =SUMIF(HELPER!$A:$A, DASHBOARD!L20, HELPER!$H:$H) -> 0
C25: YAMAHA | F25: SMK TBSM HONDA | I25: SMK NON TBSM | L25: TK
C26: =SUMIF(HELPER!$A:$A, DASHBOARD!C25, HELPER!$H:$H) -> 0 | F26: =SUMIF(HELPER!$A:$A, DASHBOARD!F25, HELPER!$H:$H) -> 0 | I26: =SUMIF(HELPER!$A:$A, DASHBOARD!I25, HELPER!$H:$H) -> 0 | L26: =SUMIF(HELPER!$A:$A, DASHBOARD!L25, HELPER!$H:$H) -> 0
C30: UMUM KAMPUS | F30: UMUM COMPANY | I30: UMUM KOMUNITAS | L30: KOSONG
C31: =SUMIF(HELPER!$A:$A, DASHBOARD!C30, HELPER!$H:$H) -> 0 | F31: =SUMIF(HELPER!$A:$A, DASHBOARD!F30, HELPER!$H:$H) -> 0 | I31: =SUMIF(HELPER!$A:$A, DASHBOARD!I30, HELPER!$H:$H) -> 0 | L31: =SUMIF(HELPER!$A:$A, DASHBOARD!L30, HELPER!$H:$H) -> 0
M40: CATEGORY PROPORTION | R40: TOP CATEGORY PROPORTION
M41: SMK NON TBSM | N41: =I26 -> 0 | O41: =N41/C10 -> 0 | P41: =IFERROR(__xludf.DUMMYFUNCTION("SPARKLINE(O41, {""Charttype"",""Bar""; ""Max"",1; ""Color1"", ""#c2795a""}) "),"") | R41: =IFERROR(__xludf.DUMMYFUNCTION("SORTN(M41:O56,16,,2,false)"),"SMK NON TBSM") -> SMK NON TBSM | S41: =IFERROR(__xludf.DUMMYFUNCTION("""COMPUTED_VALUE"""),0.0) -> 0 | T41: =IFERROR(__xludf.DUMMYFUNCTION("""COMPUTED_VALUE"""),0.0) -> 0 | U41: =IFERROR(__xludf.DUMMYFUNCTION("SPARKLINE(T41, {""Charttype"",""Bar""; ""Max"",1; ""Color1"", ""#c2795a""}) "),"")
M42: UMUM KOMUNITAS | N42: =I31 -> 0 | O42: =N42/C10 -> 0 | P42: =IFERROR(__xludf.DUMMYFUNCTION("SPARKLINE(O42, {""Charttype"",""Bar""; ""Max"",1; ""Color1"", ""#c2795a""}) "),"") | R42: =IFERROR(__xludf.DUMMYFUNCTION("""COMPUTED_VALUE"""),"UMUM KOMUNITAS") -> UMUM KOMUNITAS | S42: =IFERROR(__xludf.DUMMYFUNCTION("""COMPUTED_VALUE"""),0.0) -> 0 | T42: =IFERROR(__xludf.DUMMYFUNCTION("""COMPUTED_VALUE"""),0.0) -> 0 | U42: =IFERROR(__xludf.DUMMYFUNCTION("SPARKLINE(T42, {""Charttype"",""Bar""; ""Max"",1; ""Color1"", ""#c2795a""}) "),"")
M43: HONDA MOTOR | N43: =C16 -> 0 | O43: =N43/C10 -> 0 | P43: =IFERROR(__xludf.DUMMYFUNCTION("SPARKLINE(O43, {""Charttype"",""Bar""; ""Max"",1; ""Color1"", ""#c2795a""}) "),"") | R43: =IFERROR(__xludf.DUMMYFUNCTION("""COMPUTED_VALUE"""),"HONDA MOTOR") -> HONDA MOTOR | S43: =IFERROR(__xludf.DUMMYFUNCTION("""COMPUTED_VALUE"""),0.0) -> 0 | T43: =IFERROR(__xludf.DUMMYFUNCTION("""COMPUTED_VALUE"""),0.0) -> 0 | U43: =IFERROR(__xludf.DUMMYFUNCTION("SPARKLINE(T43, {""Charttype"",""Bar""; ""Max"",1; ""Color1"", ""#c2795a""}) "),"")
M44: UMUM CAMPANY | N44: =F31 -> 0 | O44: =N44/C10 -> 0 | P44: =IFERROR(__xludf.DUMMYFUNCTION("SPARKLINE(O44, {""Charttype"",""Bar""; ""Max"",1; ""Color1"", ""#c2795a""}) "),"") | R44: =IFERROR(__xludf.DUMMYFUNCTION("""COMPUTED_VALUE"""),"UMUM CAMPANY") -> UMUM CAMPANY | S44: =IFERROR(__xludf.DUMMYFUNCTION("""COMPUTED_VALUE"""),0.0) -> 0 | T44: =IFERROR(__xludf.DUMMYFUNCTION("""COMPUTED_VALUE"""),0.0) -> 0 | U44: =IFERROR(__xludf.DUMMYFUNCTION("SPARKLINE(T44, {""Charttype"",""Bar""; ""Max"",1; ""Color1"", ""#c2795a""}) "),"")
M45: TOYOTA | N45: =L21 -> 0 | O45: =N45/C10 -> 0 | P45: =IFERROR(__xludf.DUMMYFUNCTION("SPARKLINE(O45, {""Charttype"",""Bar""; ""Max"",1; ""Color1"", ""#c2795a""}) "),"") | R45: =IFERROR(__xludf.DUMMYFUNCTION("""COMPUTED_VALUE"""),"TOYOTA") -> TOYOTA | S45: =IFERROR(__xludf.DUMMYFUNCTION("""COMPUTED_VALUE"""),0.0) -> 0 | T45: =IFERROR(__xludf.DUMMYFUNCTION("""COMPUTED_VALUE"""),0.0) -> 0 | U45: =IFERROR(__xludf.DUMMYFUNCTION("SPARKLINE(T45, {""Charttype"",""Bar""; ""Max"",1; ""Color1"", ""#c2795a""}) "),"")
M46: YAMAHA | N46: =C26 -> 0 | O46: =N46/C10 -> 0 | P46: =IFERROR(__xludf.DUMMYFUNCTION("SPARKLINE(O46, {""Charttype"",""Bar""; ""Max"",1; ""Color1"", ""#c2795a""}) "),"") | R46: =IFERROR(__xludf.DUMMYFUNCTION("""COMPUTED_VALUE"""),"YAMAHA") -> YAMAHA | S46: =IFERROR(__xludf.DUMMYFUNCTION("""COMPUTED_VALUE"""),0.0) -> 0 | T46: =IFERROR(__xludf.DUMMYFUNCTION("""COMPUTED_VALUE"""),0.0) -> 0 | U46: =IFERROR(__xludf.DUMMYFUNCTION("SPARKLINE(T46, {""Charttype"",""Bar""; ""Max"",1; ""Color1"", ""#c2795a""}) "),"")
M47: SUZUKI | N47: =L16 -> 0 | O47: =N47/C10 -> 0 | P47: =IFERROR(__xludf.DUMMYFUNCTION("SPARKLINE(O47, {""Charttype"",""Bar""; ""Max"",1; ""Color1"", ""#c2795a""}) "),"") | R47: =IFERROR(__xludf.DUMMYFUNCTION("""COMPUTED_VALUE"""),"SUZUKI") -> SUZUKI | S47: =IFERROR(__xludf.DUMMYFUNCTION("""COMPUTED_VALUE"""),0.0) -> 0 | T47: =IFERROR(__xludf.DUMMYFUNCTION("""COMPUTED_VALUE"""),0.0) -> 0 | U47: =IFERROR(__xludf.DUMMYFUNCTION("SPARKLINE(T47, {""Charttype"",""Bar""; ""Max"",1; ""Color1"", ""#c2795a""}) "),"")
M48: HONDA MOBIL | N48: =I16 -> 0 | O48: =N48/C10 -> 0 | P48: =IFERROR(__xludf.DUMMYFUNCTION("SPARKLINE(O48, {""Charttype"",""Bar""; ""Max"",1; ""Color1"", ""#c2795a""}) "),"") | R48: =IFERROR(__xludf.DUMMYFUNCTION("""COMPUTED_VALUE"""),"HONDA MOBIL ") -> HONDA MOBIL | S48: =IFERROR(__xludf.DUMMYFUNCTION("""COMPUTED_VALUE"""),0.0) -> 0 | T48: =IFERROR(__xludf.DUMMYFUNCTION("""COMPUTED_VALUE"""),0.0) -> 0 | U48: =IFERROR(__xludf.DUMMYFUNCTION("SPARKLINE(T48, {""Charttype"",""Bar""; ""Max"",1; ""Color1"", ""#c2795a""}) "),"")
M49: MITSUBISI | N49: =F21 -> 0 | O49: =N49/C10 -> 0 | P49: =IFERROR(__xludf.DUMMYFUNCTION("SPARKLINE(O49, {""Charttype"",""Bar""; ""Max"",1; ""Color1"", ""#c2795a""}) "),"") | R49: =IFERROR(__xludf.DUMMYFUNCTION("""COMPUTED_VALUE"""),"MITSUBISI") -> MITSUBISI | S49: =IFERROR(__xludf.DUMMYFUNCTION("""COMPUTED_VALUE"""),0.0) -> 0 | T49: =IFERROR(__xludf.DUMMYFUNCTION("""COMPUTED_VALUE"""),0.0) -> 0 | U49: =IFERROR(__xludf.DUMMYFUNCTION("SPARKLINE(T49, {""Charttype"",""Bar""; ""Max"",1; ""Color1"", ""#c2795a""}) "),"")
M50: WULING | N50: =F16 -> 0 | O50: =N50/C10 -> 0 | P50: =IFERROR(__xludf.DUMMYFUNCTION("SPARKLINE(O50, {""Charttype"",""Bar""; ""Max"",1; ""Color1"", ""#c2795a""}) "),"") | R50: =IFERROR(__xludf.DUMMYFUNCTION("""COMPUTED_VALUE"""),"WULING") -> WULING | S50: =IFERROR(__xludf.DUMMYFUNCTION("""COMPUTED_VALUE"""),0.0) -> 0 | T50: =IFERROR(__xludf.DUMMYFUNCTION("""COMPUTED_VALUE"""),0.0) -> 0 | U50: =IFERROR(__xludf.DUMMYFUNCTION("SPARKLINE(T50, {""Charttype"",""Bar""; ""Max"",1; ""Color1"", ""#c2795a""}) "),"")
M51: DAIHATSU | N51: =C21 -> 0 | O51: =N51/C10 -> 0 | P51: =IFERROR(__xludf.DUMMYFUNCTION("SPARKLINE(O51, {""Charttype"",""Bar""; ""Max"",1; ""Color1"", ""#c2795a""}) "),"") | R51: =IFERROR(__xludf.DUMMYFUNCTION("""COMPUTED_VALUE"""),"DAIHATSU") -> DAIHATSU | S51: =IFERROR(__xludf.DUMMYFUNCTION("""COMPUTED_VALUE"""),0.0) -> 0 | T51: =IFERROR(__xludf.DUMMYFUNCTION("""COMPUTED_VALUE"""),0.0) -> 0 | U51: =IFERROR(__xludf.DUMMYFUNCTION("SPARKLINE(T51, {""Charttype"",""Bar""; ""Max"",1; ""Color1"", ""#c2795a""}) "),"")
M52: MAZDA | N52: =I21 -> 0 | O52: =N52/C10 -> 0 | P52: =IFERROR(__xludf.DUMMYFUNCTION("SPARKLINE(O52, {""Charttype"",""Bar""; ""Max"",1; ""Color1"", ""#c2795a""}) "),"") | R52: =IFERROR(__xludf.DUMMYFUNCTION("""COMPUTED_VALUE"""),"MAZDA") -> MAZDA | S52: =IFERROR(__xludf.DUMMYFUNCTION("""COMPUTED_VALUE"""),0.0) -> 0 | T52: =IFERROR(__xludf.DUMMYFUNCTION("""COMPUTED_VALUE"""),0.0) -> 0 | U52: =IFERROR(__xludf.DUMMYFUNCTION("SPARKLINE(T52, {""Charttype"",""Bar""; ""Max"",1; ""Color1"", ""#c2795a""}) "),"")
M53: SMK TBSM HONDA | N53: =F26 -> 0 | O53: =N53/C10 -> 0 | R53: =IFERROR(__xludf.DUMMYFUNCTION("""COMPUTED_VALUE"""),"SMK TBSM HONDA") -> SMK TBSM HONDA | S53: =IFERROR(__xludf.DUMMYFUNCTION("""COMPUTED_VALUE"""),0.0) -> 0 | T53: =IFERROR(__xludf.DUMMYFUNCTION("""COMPUTED_VALUE"""),0.0) -> 0 | U53: =IFERROR(__xludf.DUMMYFUNCTION("SPARKLINE(T53, {""Charttype"",""Bar""; ""Max"",1; ""Color1"", ""#c2795a""}) "),"")
M54: TK | N54: =L26 -> 0 | O54: =N54/C10 -> 0 | R54: =IFERROR(__xludf.DUMMYFUNCTION("""COMPUTED_VALUE"""),"TK") -> TK | S54: =IFERROR(__xludf.DUMMYFUNCTION("""COMPUTED_VALUE"""),0.0) -> 0 | T54: =IFERROR(__xludf.DUMMYFUNCTION("""COMPUTED_VALUE"""),0.0) -> 0 | U54: =IFERROR(__xludf.DUMMYFUNCTION("SPARKLINE(T54, {""Charttype"",""Bar""; ""Max"",1; ""Color1"", ""#c2795a""}) "),"")
M55: UMUM KAMPUS | N55: =C31 -> 0 | O55: =N55/C10 -> 0 | R55: =IFERROR(__xludf.DUMMYFUNCTION("""COMPUTED_VALUE"""),"UMUM KAMPUS") -> UMUM KAMPUS | S55: =IFERROR(__xludf.DUMMYFUNCTION("""COMPUTED_VALUE"""),0.0) -> 0 | T55: =IFERROR(__xludf.DUMMYFUNCTION("""COMPUTED_VALUE"""),0.0) -> 0 | U55: =IFERROR(__xludf.DUMMYFUNCTION("SPARKLINE(T55, {""Charttype"",""Bar""; ""Max"",1; ""Color1"", ""#c2795a""}) "),"")
M56: KOSONG | N56: =L31 -> 0 | O56: =N56/C10 -> 0 | R56: =IFERROR(__xludf.DUMMYFUNCTION("""COMPUTED_VALUE"""),"KOSONG") -> KOSONG | S56: =IFERROR(__xludf.DUMMYFUNCTION("""COMPUTED_VALUE"""),0.0) -> 0 | T56: =IFERROR(__xludf.DUMMYFUNCTION("""COMPUTED_VALUE"""),0.0) -> 0 | U56: =IFERROR(__xludf.DUMMYFUNCTION("SPARKLINE(T56, {""Charttype"",""Bar""; ""Max"",1; ""Color1"", ""#c2795a""}) "),"")

Sheet HELPER
A1: IITEM CODE | B1: INSTANSI | C1: CUSTOMER | D1: DATE | E1: PRODUCT | F1: QTY | G1: PRICE | H1: TOTAL PRICE | I1: Column 9 | J1: Column 10 | K1: Column 12 | L1: Column 13 | M1: Column 14 | N1: Column 15 | O1: Column 16 | P1: Column 17
A2: =IFERROR(__xludf.DUMMYFUNCTION("FILTER(Table1,Table1[DATE]>=DASHBOARD!D6,Table1[DATE]<=DASHBOARD!D7)"),"") | C2: =IFERROR(__xludf.DUMMYFUNCTION("""COMPUTED_VALUE"""),"Pak Brili Agung") -> Pak Brili Agung | D2: =IFERROR(__xludf.DUMMYFUNCTION("""COMPUTED_VALUE"""),46113.0) -> 46113 | E2: =IFERROR(__xludf.DUMMYFUNCTION("""COMPUTED_VALUE"""),"Kaos Polo Biru Muda") -> Kaos Polo Biru Muda | F2: =IFERROR(__xludf.DUMMYFUNCTION("""COMPUTED_VALUE"""),38.0) -> 38 | G2: =IFERROR(__xludf.DUMMYFUNCTION("""COMPUTED_VALUE"""),79000.0) -> 79000 | H2: =IFERROR(__xludf.DUMMYFUNCTION("""COMPUTED_VALUE"""),3002000.0) -> 3002000 | I2: =IFERROR(__xludf.DUMMYFUNCTION("""COMPUTED_VALUE"""),1.094E7) -> 10940000
C3: =IFERROR(__xludf.DUMMYFUNCTION("""COMPUTED_VALUE"""),"Pak Brili Agung") -> Pak Brili Agung | D3: =IFERROR(__xludf.DUMMYFUNCTION("""COMPUTED_VALUE"""),46113.0) -> 46113 | E3: =IFERROR(__xludf.DUMMYFUNCTION("""COMPUTED_VALUE"""),"Kaos Polo Biru Muda") -> Kaos Polo Biru Muda | F3: =IFERROR(__xludf.DUMMYFUNCTION("""COMPUTED_VALUE"""),2.0) -> 2 | G3: =IFERROR(__xludf.DUMMYFUNCTION("""COMPUTED_VALUE"""),89000.0) -> 89000 | H3: =IFERROR(__xludf.DUMMYFUNCTION("""COMPUTED_VALUE"""),178000.0) -> 178000
C4: =IFERROR(__xludf.DUMMYFUNCTION("""COMPUTED_VALUE"""),"Pak Brili Agung") -> Pak Brili Agung | D4: =IFERROR(__xludf.DUMMYFUNCTION("""COMPUTED_VALUE"""),46113.0) -> 46113 | E4: =IFERROR(__xludf.DUMMYFUNCTION("""COMPUTED_VALUE"""),"Kaos Polo Biru Navy") -> Kaos Polo Biru Navy | F4: =IFERROR(__xludf.DUMMYFUNCTION("""COMPUTED_VALUE"""),38.0) -> 38 | G4: =IFERROR(__xludf.DUMMYFUNCTION("""COMPUTED_VALUE"""),79000.0) -> 79000 | H4: =IFERROR(__xludf.DUMMYFUNCTION("""COMPUTED_VALUE"""),3002000.0) -> 3002000 | K4: {=UNIQUE(A:A)} -> IITEM CODE | L4: Product | O4: Instansi | P4: Sales
C5: =IFERROR(__xludf.DUMMYFUNCTION("""COMPUTED_VALUE"""),"Pak Brili Agung") -> Pak Brili Agung | D5: =IFERROR(__xludf.DUMMYFUNCTION("""COMPUTED_VALUE"""),46113.0) -> 46113 | E5: =IFERROR(__xludf.DUMMYFUNCTION("""COMPUTED_VALUE"""),"Kaos Polo Biru Navy") -> Kaos Polo Biru Navy | F5: =IFERROR(__xludf.DUMMYFUNCTION("""COMPUTED_VALUE"""),2.0) -> 2 | G5: =IFERROR(__xludf.DUMMYFUNCTION("""COMPUTED_VALUE"""),89000.0) -> 89000 | H5: =IFERROR(__xludf.DUMMYFUNCTION("""COMPUTED_VALUE"""),178000.0) -> 178000 | J5: =IFERROR(__xludf.DUMMYFUNCTION("""COMPUTED_VALUE""")," ") | L5: Seragam PDH Custom | M5: =SUMIFS(H2:H45,E2:E45,L5) -> 0 | O5: =IFERROR(__xludf.DUMMYFUNCTION("SORTN(K40:L71,5,,2,0)"),"Seragam Mekanik Honda") -> Seragam Mekanik Honda | P5: =IFERROR(__xludf.DUMMYFUNCTION("""COMPUTED_VALUE"""),450000.0) -> 450000
C6: =IFERROR(__xludf.DUMMYFUNCTION("""COMPUTED_VALUE"""),"Pak Brili Agung") -> Pak Brili Agung | D6: =IFERROR(__xludf.DUMMYFUNCTION("""COMPUTED_VALUE"""),46113.0) -> 46113 | E6: =IFERROR(__xludf.DUMMYFUNCTION("""COMPUTED_VALUE"""),"Kaos Polo Cream") -> Kaos Polo Cream | F6: =IFERROR(__xludf.DUMMYFUNCTION("""COMPUTED_VALUE"""),38.0) -> 38 | G6: =IFERROR(__xludf.DUMMYFUNCTION("""COMPUTED_VALUE"""),79000.0) -> 79000 | H6: =IFERROR(__xludf.DUMMYFUNCTION("""COMPUTED_VALUE"""),3002000.0) -> 3002000 | L6: Honda Mekanik 1 set | M6: =SUMIFS(H3:H46,E3:E46,L6) -> 0 | O6: =IFERROR(__xludf.DUMMYFUNCTION("""COMPUTED_VALUE"""),"Wearpack Mitsubitshi") -> Wearpack Mitsubitshi | P6: =IFERROR(__xludf.DUMMYFUNCTION("""COMPUTED_VALUE"""),440000.0) -> 440000
C7: =IFERROR(__xludf.DUMMYFUNCTION("""COMPUTED_VALUE"""),"Pak Brili Agung") -> Pak Brili Agung | D7: =IFERROR(__xludf.DUMMYFUNCTION("""COMPUTED_VALUE"""),46113.0) -> 46113 | E7: =IFERROR(__xludf.DUMMYFUNCTION("""COMPUTED_VALUE"""),"Kaos Polo Cream") -> Kaos Polo Cream | F7: =IFERROR(__xludf.DUMMYFUNCTION("""COMPUTED_VALUE"""),2.0) -> 2 | G7: =IFERROR(__xludf.DUMMYFUNCTION("""COMPUTED_VALUE"""),89000.0) -> 89000 | H7: =IFERROR(__xludf.DUMMYFUNCTION("""COMPUTED_VALUE"""),178000.0) -> 178000 | L7: Toyota tanpa bordir | M7: =SUMIFS(H4:H47,E4:E47,L7) -> 0 | O7: =IFERROR(__xludf.DUMMYFUNCTION("""COMPUTED_VALUE"""),"Seragam PDH Custom") -> Seragam PDH Custom | P7: =IFERROR(__xludf.DUMMYFUNCTION("""COMPUTED_VALUE"""),0.0) -> 0
C8: =IFERROR(__xludf.DUMMYFUNCTION("""COMPUTED_VALUE"""),"Pak Brili Agung") -> Pak Brili Agung | D8: =IFERROR(__xludf.DUMMYFUNCTION("""COMPUTED_VALUE"""),46113.0) -> 46113 | E8: =IFERROR(__xludf.DUMMYFUNCTION("""COMPUTED_VALUE"""),"Apron") -> Apron | F8: =IFERROR(__xludf.DUMMYFUNCTION("""COMPUTED_VALUE"""),40.0) -> 40 | G8: =IFERROR(__xludf.DUMMYFUNCTION("""COMPUTED_VALUE"""),35000.0) -> 35000 | H8: =IFERROR(__xludf.DUMMYFUNCTION("""COMPUTED_VALUE"""),1400000.0) -> 1400000 | L8: Seragam PDH | M8: =SUMIFS(H5:H48,E5:E48,L8) -> 0 | O8: =IFERROR(__xludf.DUMMYFUNCTION("""COMPUTED_VALUE"""),"Honda Mekanik 1 set") -> Honda Mekanik 1 set | P8: =IFERROR(__xludf.DUMMYFUNCTION("""COMPUTED_VALUE"""),0.0) -> 0
C9: =IFERROR(__xludf.DUMMYFUNCTION("""COMPUTED_VALUE"""),"Ibu Sarmauli") -> Ibu Sarmauli | D9: =IFERROR(__xludf.DUMMYFUNCTION("""COMPUTED_VALUE"""),46114.0) -> 46114 | E9: =IFERROR(__xludf.DUMMYFUNCTION("""COMPUTED_VALUE"""),"Celemek SPPG Kecil") -> Celemek SPPG Kecil | F9: =IFERROR(__xludf.DUMMYFUNCTION("""COMPUTED_VALUE"""),179.0) -> 179 | G9: =IFERROR(__xludf.DUMMYFUNCTION("""COMPUTED_VALUE"""),27000.0) -> 27000 | H9: =IFERROR(__xludf.DUMMYFUNCTION("""COMPUTED_VALUE"""),4833000.0) -> 4833000 | I9: =IFERROR(__xludf.DUMMYFUNCTION("""COMPUTED_VALUE"""),4833000.0) -> 4833000 | L9: Kaos Lapangan | M9: =SUMIFS(H6:H49,E6:E49,L9) -> 0 | O9: =IFERROR(__xludf.DUMMYFUNCTION("""COMPUTED_VALUE"""),"Toyota tanpa bordir") -> Toyota tanpa bordir | P9: =IFERROR(__xludf.DUMMYFUNCTION("""COMPUTED_VALUE"""),0.0) -> 0
C10: =IFERROR(__xludf.DUMMYFUNCTION("""COMPUTED_VALUE"""),"Pak Abdul") -> Pak Abdul | D10: =IFERROR(__xludf.DUMMYFUNCTION("""COMPUTED_VALUE"""),46118.0) -> 46118 | E10: =IFERROR(__xludf.DUMMYFUNCTION("""COMPUTED_VALUE"""),"Seragam Mekanik 1 Set") -> Seragam Mekanik 1 Set | F10: =IFERROR(__xludf.DUMMYFUNCTION("""COMPUTED_VALUE"""),4.0) -> 4 | G10: =IFERROR(__xludf.DUMMYFUNCTION("""COMPUTED_VALUE"""),250000.0) -> 250000 | H10: =IFERROR(__xludf.DUMMYFUNCTION("""COMPUTED_VALUE"""),1000000.0) -> 1000000 | L10: wearpacknya Custom | M10: =SUMIFS(H7:H50,E7:E50,L10) -> 0
C11: =IFERROR(__xludf.DUMMYFUNCTION("""COMPUTED_VALUE"""),"Pak Abdul") -> Pak Abdul | D11: =IFERROR(__xludf.DUMMYFUNCTION("""COMPUTED_VALUE"""),46118.0) -> 46118 | E11: =IFERROR(__xludf.DUMMYFUNCTION("""COMPUTED_VALUE"""),"Seragam Mekanik 1 Set") -> Seragam Mekanik 1 Set | F11: =IFERROR(__xludf.DUMMYFUNCTION("""COMPUTED_VALUE"""),1.0) -> 1 | G11: =IFERROR(__xludf.DUMMYFUNCTION("""COMPUTED_VALUE"""),260000.0) -> 260000 | H11: =IFERROR(__xludf.DUMMYFUNCTION("""COMPUTED_VALUE"""),260000.0) -> 260000 | L11: Seragam Mekanik Honda Mobil 1 Set | M11: =SUMIFS(H8:H51,E8:E51,L11) -> 0
C12: =IFERROR(__xludf.DUMMYFUNCTION("""COMPUTED_VALUE"""),"Pak Abdul") -> Pak Abdul | D12: =IFERROR(__xludf.DUMMYFUNCTION("""COMPUTED_VALUE"""),46118.0) -> 46118 | E12: =IFERROR(__xludf.DUMMYFUNCTION("""COMPUTED_VALUE"""),"Seragam Mekanik 1 Set") -> Seragam Mekanik 1 Set | F12: =IFERROR(__xludf.DUMMYFUNCTION("""COMPUTED_VALUE"""),1.0) -> 1 | G12: =IFERROR(__xludf.DUMMYFUNCTION("""COMPUTED_VALUE"""),270000.0) -> 270000 | H12: =IFERROR(__xludf.DUMMYFUNCTION("""COMPUTED_VALUE"""),270000.0) -> 270000 | I12: =IFERROR(__xludf.DUMMYFUNCTION("""COMPUTED_VALUE"""),1530000.0) -> 1530000 | L12: Seragam Mekanik set + Bordir Nama Dealer | M12: =SUMIFS(H9:H52,E9:E52,L12) -> 0
C13: =IFERROR(__xludf.DUMMYFUNCTION("""COMPUTED_VALUE""")," PT Anugerah Kasih Putera (AKSP)") -> PT Anugerah Kasih Putera (AKSP) | D13: =IFERROR(__xludf.DUMMYFUNCTION("""COMPUTED_VALUE"""),46119.0) -> 46119 | E13: =IFERROR(__xludf.DUMMYFUNCTION("""COMPUTED_VALUE"""),"Seragam Honda (Teknisi, Foreman, Cuci)") -> Seragam Honda (Teknisi, Foreman, Cuci) | F13: =IFERROR(__xludf.DUMMYFUNCTION("""COMPUTED_VALUE"""),36.0) -> 36 | G13: =IFERROR(__xludf.DUMMYFUNCTION("""COMPUTED_VALUE"""),110000.0) -> 110000 | H13: =IFERROR(__xludf.DUMMYFUNCTION("""COMPUTED_VALUE"""),3960000.0) -> 3960000 | L13: Seragam Staff Bengkel + Bordir Nama Dealer | M13: =SUMIFS(H10:H53,E10:E53,L13) -> 0
C14: =IFERROR(__xludf.DUMMYFUNCTION("""COMPUTED_VALUE""")," PT Anugerah Kasih Putera (AKSP)") -> PT Anugerah Kasih Putera (AKSP) | D14: =IFERROR(__xludf.DUMMYFUNCTION("""COMPUTED_VALUE"""),46119.0) -> 46119 | E14: =IFERROR(__xludf.DUMMYFUNCTION("""COMPUTED_VALUE"""),"Seragam Honda (Teknisi, Foreman, Cuci)") -> Seragam Honda (Teknisi, Foreman, Cuci) | F14: =IFERROR(__xludf.DUMMYFUNCTION("""COMPUTED_VALUE"""),3.0) -> 3 | G14: =IFERROR(__xludf.DUMMYFUNCTION("""COMPUTED_VALUE"""),120000.0) -> 120000 | H14: =IFERROR(__xludf.DUMMYFUNCTION("""COMPUTED_VALUE"""),360000.0) -> 360000 | L14: Seragam PDI Set + Bordir Nama Dealer | M14: =SUMIFS(H11:H54,E11:E54,L14) -> 0
C15: =IFERROR(__xludf.DUMMYFUNCTION("""COMPUTED_VALUE""")," PT Anugerah Kasih Putera (AKSP)") -> PT Anugerah Kasih Putera (AKSP) | D15: =IFERROR(__xludf.DUMMYFUNCTION("""COMPUTED_VALUE"""),46119.0) -> 46119 | E15: =IFERROR(__xludf.DUMMYFUNCTION("""COMPUTED_VALUE"""),"Seragam Honda (Teknisi, Foreman, Cuci)") -> Seragam Honda (Teknisi, Foreman, Cuci) | F15: =IFERROR(__xludf.DUMMYFUNCTION("""COMPUTED_VALUE"""),1.0) -> 1 | G15: =IFERROR(__xludf.DUMMYFUNCTION("""COMPUTED_VALUE"""),130000.0) -> 130000 | H15: =IFERROR(__xludf.DUMMYFUNCTION("""COMPUTED_VALUE"""),130000.0) -> 130000 | L15: Seragam Counter + Bordir Nama Dealer | M15: =SUMIFS(H12:H55,E12:E55,L15) -> 0
C16: =IFERROR(__xludf.DUMMYFUNCTION("""COMPUTED_VALUE"""),"PT Anugerah Kasih Putera (Bantul)") -> PT Anugerah Kasih Putera (Bantul) | D16: =IFERROR(__xludf.DUMMYFUNCTION("""COMPUTED_VALUE"""),46119.0) -> 46119 | E16: =IFERROR(__xludf.DUMMYFUNCTION("""COMPUTED_VALUE"""),"Seragam Honda (Teknisi)") -> Seragam Honda (Teknisi) | F16: =IFERROR(__xludf.DUMMYFUNCTION("""COMPUTED_VALUE"""),12.0) -> 12 | G16: =IFERROR(__xludf.DUMMYFUNCTION("""COMPUTED_VALUE"""),110000.0) -> 110000 | H16: =IFERROR(__xludf.DUMMYFUNCTION("""COMPUTED_VALUE"""),1320000.0) -> 1320000 | I16: =IFERROR(__xludf.DUMMYFUNCTION("""COMPUTED_VALUE"""),5890000.0) -> 5890000 | L16: Seragam Driver | M16: =SUMIFS(H13:H56,E13:E56,L16) -> 0
C17: =IFERROR(__xludf.DUMMYFUNCTION("""COMPUTED_VALUE"""),"PT Anugerah Kasih Putera (Bantul)") -> PT Anugerah Kasih Putera (Bantul) | D17: =IFERROR(__xludf.DUMMYFUNCTION("""COMPUTED_VALUE"""),46119.0) -> 46119 | E17: =IFERROR(__xludf.DUMMYFUNCTION("""COMPUTED_VALUE"""),"Seragam Honda (Teknisi)") -> Seragam Honda (Teknisi) | F17: =IFERROR(__xludf.DUMMYFUNCTION("""COMPUTED_VALUE"""),1.0) -> 1 | G17: =IFERROR(__xludf.DUMMYFUNCTION("""COMPUTED_VALUE"""),120000.0) -> 120000 | H17: =IFERROR(__xludf.DUMMYFUNCTION("""COMPUTED_VALUE"""),120000.0) -> 120000 | L17: Seragam PDH Custom | M17: =SUMIFS(H14:H57,E14:E57,L17) -> 0
C18: =IFERROR(__xludf.DUMMYFUNCTION("""COMPUTED_VALUE"""),"Ibu Sarmauli") -> Ibu Sarmauli | D18: =IFERROR(__xludf.DUMMYFUNCTION("""COMPUTED_VALUE"""),46125.0) -> 46125 | E18: =IFERROR(__xludf.DUMMYFUNCTION("""COMPUTED_VALUE"""),"Kaos Polo SPPG") -> Kaos Polo SPPG | F18: =IFERROR(__xludf.DUMMYFUNCTION("""COMPUTED_VALUE"""),54.0) -> 54 | G18: =IFERROR(__xludf.DUMMYFUNCTION("""COMPUTED_VALUE"""),67000.0) -> 67000 | H18: =IFERROR(__xludf.DUMMYFUNCTION("""COMPUTED_VALUE"""),3618000.0) -> 3618000 | I18: =IFERROR(__xludf.DUMMYFUNCTION("""COMPUTED_VALUE"""),1.4022E7) -> 14022000 | L18: wearpacknya Custom | M18: =SUMIFS(H15:H58,E15:E58,L18) -> 0
C19: =IFERROR(__xludf.DUMMYFUNCTION("""COMPUTED_VALUE"""),"Ibu Sarmauli") -> Ibu Sarmauli | D19: =IFERROR(__xludf.DUMMYFUNCTION("""COMPUTED_VALUE"""),46125.0) -> 46125 | E19: =IFERROR(__xludf.DUMMYFUNCTION("""COMPUTED_VALUE"""),"Kaos Polo SPPG") -> Kaos Polo SPPG | F19: =IFERROR(__xludf.DUMMYFUNCTION("""COMPUTED_VALUE"""),18.0) -> 18 | G19: =IFERROR(__xludf.DUMMYFUNCTION("""COMPUTED_VALUE"""),72000.0) -> 72000 | H19: =IFERROR(__xludf.DUMMYFUNCTION("""COMPUTED_VALUE"""),1296000.0) -> 1296000 | L19: Seragam Mekanik Honda 1 set | M19: =SUMIFS(H16:H59,E16:E59,L19) -> 0
C20: =IFERROR(__xludf.DUMMYFUNCTION("""COMPUTED_VALUE"""),"Ibu Sarmauli") -> Ibu Sarmauli | D20: =IFERROR(__xludf.DUMMYFUNCTION("""COMPUTED_VALUE"""),46125.0) -> 46125 | E20: =IFERROR(__xludf.DUMMYFUNCTION("""COMPUTED_VALUE"""),"Kaos Polo SPPG") -> Kaos Polo SPPG | F20: =IFERROR(__xludf.DUMMYFUNCTION("""COMPUTED_VALUE"""),72.0) -> 72 | G20: =IFERROR(__xludf.DUMMYFUNCTION("""COMPUTED_VALUE"""),77000.0) -> 77000 | H20: =IFERROR(__xludf.DUMMYFUNCTION("""COMPUTED_VALUE"""),5544000.0) -> 5544000 | L20: Topi | M20: =SUMIFS(H17:H60,E17:E60,L20) -> 0
C21: =IFERROR(__xludf.DUMMYFUNCTION("""COMPUTED_VALUE"""),"Ibu Sarmauli") -> Ibu Sarmauli | D21: =IFERROR(__xludf.DUMMYFUNCTION("""COMPUTED_VALUE"""),46125.0) -> 46125 | E21: =IFERROR(__xludf.DUMMYFUNCTION("""COMPUTED_VALUE"""),"Kaos Polo SPPG") -> Kaos Polo SPPG | F21: =IFERROR(__xludf.DUMMYFUNCTION("""COMPUTED_VALUE"""),24.0) -> 24 | G21: =IFERROR(__xludf.DUMMYFUNCTION("""COMPUTED_VALUE"""),87000.0) -> 87000 | H21: =IFERROR(__xludf.DUMMYFUNCTION("""COMPUTED_VALUE"""),2088000.0) -> 2088000 | L21: Apron | M21: =SUMIFS(H18:H61,E18:E61,L21) -> 0
C22: =IFERROR(__xludf.DUMMYFUNCTION("""COMPUTED_VALUE"""),"Ibu Sarmauli") -> Ibu Sarmauli | D22: =IFERROR(__xludf.DUMMYFUNCTION("""COMPUTED_VALUE"""),46125.0) -> 46125 | E22: =IFERROR(__xludf.DUMMYFUNCTION("""COMPUTED_VALUE"""),"Kaos Polo SPPG") -> Kaos Polo SPPG | F22: =IFERROR(__xludf.DUMMYFUNCTION("""COMPUTED_VALUE"""),18.0) -> 18 | G22: =IFERROR(__xludf.DUMMYFUNCTION("""COMPUTED_VALUE"""),82000.0) -> 82000 | H22: =IFERROR(__xludf.DUMMYFUNCTION("""COMPUTED_VALUE"""),1476000.0) -> 1476000 | L22: Wearpack Toyota | M22: =SUMIFS(H19:H62,E19:E62,L22) -> 0
C23: =IFERROR(__xludf.DUMMYFUNCTION("""COMPUTED_VALUE""")," Pak Shidqi") -> Pak Shidqi | D23: =IFERROR(__xludf.DUMMYFUNCTION("""COMPUTED_VALUE"""),46128.0) -> 46128 | E23: =IFERROR(__xludf.DUMMYFUNCTION("""COMPUTED_VALUE"""),"Wearpack") -> Wearpack | F23: =IFERROR(__xludf.DUMMYFUNCTION("""COMPUTED_VALUE"""),3.0) -> 3 | G23: =IFERROR(__xludf.DUMMYFUNCTION("""COMPUTED_VALUE"""),280000.0) -> 280000 | H23: =IFERROR(__xludf.DUMMYFUNCTION("""COMPUTED_VALUE"""),840000.0) -> 840000 | I23: =IFERROR(__xludf.DUMMYFUNCTION("""COMPUTED_VALUE"""),1.534E7) -> 15340000 | L23: Seragam Mekanik Honda 1 Set (Topi+Apron) | M23: =SUMIFS(H20:H63,E20:E63,L23) -> 0
C24: =IFERROR(__xludf.DUMMYFUNCTION("""COMPUTED_VALUE"""),"Pak Dwi ") -> Pak Dwi | D24: =IFERROR(__xludf.DUMMYFUNCTION("""COMPUTED_VALUE"""),46128.0) -> 46128 | E24: =IFERROR(__xludf.DUMMYFUNCTION("""COMPUTED_VALUE"""),"Seragam TSM ") -> Seragam TSM | F24: =IFERROR(__xludf.DUMMYFUNCTION("""COMPUTED_VALUE"""),49.0) -> 49 | G24: =IFERROR(__xludf.DUMMYFUNCTION("""COMPUTED_VALUE"""),220000.0) -> 220000 | H24: =IFERROR(__xludf.DUMMYFUNCTION("""COMPUTED_VALUE"""),1.078E7) -> 10780000 | L24: Wearpack Akademi Yamaha | M24: =SUMIFS(H21:H64,E21:E64,L24) -> 0
C25: =IFERROR(__xludf.DUMMYFUNCTION("""COMPUTED_VALUE"""),"Pak Dwi ") -> Pak Dwi | D25: =IFERROR(__xludf.DUMMYFUNCTION("""COMPUTED_VALUE"""),46128.0) -> 46128 | E25: =IFERROR(__xludf.DUMMYFUNCTION("""COMPUTED_VALUE"""),"Seragam TSM ") -> Seragam TSM | F25: =IFERROR(__xludf.DUMMYFUNCTION("""COMPUTED_VALUE"""),2.0) -> 2 | G25: =IFERROR(__xludf.DUMMYFUNCTION("""COMPUTED_VALUE"""),230000.0) -> 230000 | H25: =IFERROR(__xludf.DUMMYFUNCTION("""COMPUTED_VALUE"""),460000.0) -> 460000 | L25: Seragam Mekanik Honda | M25: =SUMIFS(H22:H65,E22:E65,L25) -> 450000 | N25: 4
C26: =IFERROR(__xludf.DUMMYFUNCTION("""COMPUTED_VALUE"""),"Pak Dwi ") -> Pak Dwi | D26: =IFERROR(__xludf.DUMMYFUNCTION("""COMPUTED_VALUE"""),46128.0) -> 46128 | E26: =IFERROR(__xludf.DUMMYFUNCTION("""COMPUTED_VALUE"""),"Seragam TSM ") -> Seragam TSM | F26: =IFERROR(__xludf.DUMMYFUNCTION("""COMPUTED_VALUE"""),13.0) -> 13 | G26: =IFERROR(__xludf.DUMMYFUNCTION("""COMPUTED_VALUE"""),200000.0) -> 200000 | H26: =IFERROR(__xludf.DUMMYFUNCTION("""COMPUTED_VALUE"""),2600000.0) -> 2600000 | L26: Revisi Lengan dan Ukuran Wearpack | M26: =SUMIFS(H23:H66,E23:E66,L26) -> 0
C27: =IFERROR(__xludf.DUMMYFUNCTION("""COMPUTED_VALUE"""),"Pak Dwi ") -> Pak Dwi | D27: =IFERROR(__xludf.DUMMYFUNCTION("""COMPUTED_VALUE"""),46128.0) -> 46128 | E27: =IFERROR(__xludf.DUMMYFUNCTION("""COMPUTED_VALUE"""),"Seragam TSM ") -> Seragam TSM | F27: =IFERROR(__xludf.DUMMYFUNCTION("""COMPUTED_VALUE"""),2.0) -> 2 | G27: =IFERROR(__xludf.DUMMYFUNCTION("""COMPUTED_VALUE"""),210000.0) -> 210000 | H27: =IFERROR(__xludf.DUMMYFUNCTION("""COMPUTED_VALUE"""),420000.0) -> 420000 | L27: Topi Custom | M27: =SUMIFS(H24:H67,E24:E67,L27) -> 0
C28: =IFERROR(__xludf.DUMMYFUNCTION("""COMPUTED_VALUE"""),"Pak Dwi ") -> Pak Dwi | D28: =IFERROR(__xludf.DUMMYFUNCTION("""COMPUTED_VALUE"""),46128.0) -> 46128 | E28: =IFERROR(__xludf.DUMMYFUNCTION("""COMPUTED_VALUE"""),"Seragam TSM ") -> Seragam TSM | F28: =IFERROR(__xludf.DUMMYFUNCTION("""COMPUTED_VALUE"""),1.0) -> 1 | G28: =IFERROR(__xludf.DUMMYFUNCTION("""COMPUTED_VALUE"""),240000.0) -> 240000 | H28: =IFERROR(__xludf.DUMMYFUNCTION("""COMPUTED_VALUE"""),240000.0) -> 240000 | L28: Wearpack Mitsubitshi | M28: =SUMIFS(H25:H68,E25:E68,L28) -> 7800000
C29: =IFERROR(__xludf.DUMMYFUNCTION("""COMPUTED_VALUE""")," PT Anugerah Kasih Putera (ASP)") -> PT Anugerah Kasih Putera (ASP) | D29: =IFERROR(__xludf.DUMMYFUNCTION("""COMPUTED_VALUE"""),46129.0) -> 46129 | E29: =IFERROR(__xludf.DUMMYFUNCTION("""COMPUTED_VALUE"""),"Seragam Honda (Teknisi)") -> Seragam Honda (Teknisi) | F29: =IFERROR(__xludf.DUMMYFUNCTION("""COMPUTED_VALUE"""),27.0) -> 27 | G29: =IFERROR(__xludf.DUMMYFUNCTION("""COMPUTED_VALUE"""),110000.0) -> 110000 | H29: =IFERROR(__xludf.DUMMYFUNCTION("""COMPUTED_VALUE"""),2970000.0) -> 2970000 | I29: =IFERROR(__xludf.DUMMYFUNCTION("""COMPUTED_VALUE"""),3580000.0) -> 3580000 | L29: Seragam Mekanik Honda Set (Atasan+Celana) | M29: =SUMIFS(H26:H69,E26:E69,L29) -> 0
C30: =IFERROR(__xludf.DUMMYFUNCTION("""COMPUTED_VALUE""")," PT Anugerah Kasih Putera (ASP)") -> PT Anugerah Kasih Putera (ASP) | D30: =IFERROR(__xludf.DUMMYFUNCTION("""COMPUTED_VALUE"""),46129.0) -> 46129 | E30: =IFERROR(__xludf.DUMMYFUNCTION("""COMPUTED_VALUE"""),"Seragam Honda (Teknisi)") -> Seragam Honda (Teknisi) | F30: =IFERROR(__xludf.DUMMYFUNCTION("""COMPUTED_VALUE"""),4.0) -> 4 | G30: =IFERROR(__xludf.DUMMYFUNCTION("""COMPUTED_VALUE"""),120000.0) -> 120000 | H30: =IFERROR(__xludf.DUMMYFUNCTION("""COMPUTED_VALUE"""),480000.0) -> 480000 | L30: Celemek SPPG | M30: =SUMIFS(H27:H70,E27:E70,L30) -> 0
C31: =IFERROR(__xludf.DUMMYFUNCTION("""COMPUTED_VALUE""")," PT Anugerah Kasih Putera (ASP)") -> PT Anugerah Kasih Putera (ASP) | D31: =IFERROR(__xludf.DUMMYFUNCTION("""COMPUTED_VALUE"""),46129.0) -> 46129 | E31: =IFERROR(__xludf.DUMMYFUNCTION("""COMPUTED_VALUE"""),"Seragam Honda (Teknisi)") -> Seragam Honda (Teknisi) | F31: =IFERROR(__xludf.DUMMYFUNCTION("""COMPUTED_VALUE"""),1.0) -> 1 | G31: =IFERROR(__xludf.DUMMYFUNCTION("""COMPUTED_VALUE"""),130000.0) -> 130000 | H31: =IFERROR(__xludf.DUMMYFUNCTION("""COMPUTED_VALUE"""),130000.0) -> 130000 | L31: Seragam HRC Honda | M31: =SUMIFS(H28:H71,E28:E71,L31) -> 0
C32: =IFERROR(__xludf.DUMMYFUNCTION("""COMPUTED_VALUE"""),"Pradika Hermawan") -> Pradika Hermawan | D32: =IFERROR(__xludf.DUMMYFUNCTION("""COMPUTED_VALUE"""),46132.0) -> 46132 | E32: =IFERROR(__xludf.DUMMYFUNCTION("""COMPUTED_VALUE"""),"Kaos") -> Kaos | F32: =IFERROR(__xludf.DUMMYFUNCTION("""COMPUTED_VALUE"""),13.0) -> 13 | G32: =IFERROR(__xludf.DUMMYFUNCTION("""COMPUTED_VALUE"""),85000.0) -> 85000 | H32: =IFERROR(__xludf.DUMMYFUNCTION("""COMPUTED_VALUE"""),1105000.0) -> 1105000 | I32: =IFERROR(__xludf.DUMMYFUNCTION("""COMPUTED_VALUE"""),1895000.0) -> 1895000 | L32: Mitsubishi sales | M32: =SUMIFS(H29:H72,E29:E72,L32) -> 0
C33: =IFERROR(__xludf.DUMMYFUNCTION("""COMPUTED_VALUE"""),"Pradika Hermawan") -> Pradika Hermawan | D33: =IFERROR(__xludf.DUMMYFUNCTION("""COMPUTED_VALUE"""),46132.0) -> 46132 | E33: =IFERROR(__xludf.DUMMYFUNCTION("""COMPUTED_VALUE"""),"Kaos") -> Kaos | F33: =IFERROR(__xludf.DUMMYFUNCTION("""COMPUTED_VALUE"""),5.0) -> 5 | G33: =IFERROR(__xludf.DUMMYFUNCTION("""COMPUTED_VALUE"""),95000.0) -> 95000 | H33: =IFERROR(__xludf.DUMMYFUNCTION("""COMPUTED_VALUE"""),475000.0) -> 475000 | L33: Apron honda & Topi Mekanik Honda Motor Putih | M33: =SUMIFS(H30:H73,E30:E73,L33) -> 0
C34: =IFERROR(__xludf.DUMMYFUNCTION("""COMPUTED_VALUE"""),"Pradika Hermawan") -> Pradika Hermawan | D34: =IFERROR(__xludf.DUMMYFUNCTION("""COMPUTED_VALUE"""),46132.0) -> 46132 | E34: =IFERROR(__xludf.DUMMYFUNCTION("""COMPUTED_VALUE"""),"Kaos") -> Kaos | F34: =IFERROR(__xludf.DUMMYFUNCTION("""COMPUTED_VALUE"""),3.0) -> 3 | G34: =IFERROR(__xludf.DUMMYFUNCTION("""COMPUTED_VALUE"""),105000.0) -> 105000 | H34: =IFERROR(__xludf.DUMMYFUNCTION("""COMPUTED_VALUE"""),315000.0) -> 315000 | L34: Seragam Suzuki tanpa Bordir | M34: =SUMIFS(H31:H74,E31:E74,L34) -> 0
C35: =IFERROR(__xludf.DUMMYFUNCTION("""COMPUTED_VALUE"""),"PT Anugerah Kasih Putera (Body and Paint)") -> PT Anugerah Kasih Putera (Body and Paint) | D35: =IFERROR(__xludf.DUMMYFUNCTION("""COMPUTED_VALUE"""),46133.0) -> 46133 | E35: =IFERROR(__xludf.DUMMYFUNCTION("""COMPUTED_VALUE"""),"Seragam Honda (Teknisi)") -> Seragam Honda (Teknisi) | F35: =IFERROR(__xludf.DUMMYFUNCTION("""COMPUTED_VALUE"""),34.0) -> 34 | G35: =IFERROR(__xludf.DUMMYFUNCTION("""COMPUTED_VALUE"""),110000.0) -> 110000 | H35: =IFERROR(__xludf.DUMMYFUNCTION("""COMPUTED_VALUE"""),3740000.0) -> 3740000 | I35: =IFERROR(__xludf.DUMMYFUNCTION("""COMPUTED_VALUE"""),4700000.0) -> 4700000 | L35: Dasi | M35: =SUMIFS(H32:H75,E32:E75,L35) -> 0
C36: =IFERROR(__xludf.DUMMYFUNCTION("""COMPUTED_VALUE"""),"PT Anugerah Kasih Putera (Body and Paint)") -> PT Anugerah Kasih Putera (Body and Paint) | D36: =IFERROR(__xludf.DUMMYFUNCTION("""COMPUTED_VALUE"""),46133.0) -> 46133 | E36: =IFERROR(__xludf.DUMMYFUNCTION("""COMPUTED_VALUE"""),"Seragam Honda (Teknisi)") -> Seragam Honda (Teknisi) | F36: =IFERROR(__xludf.DUMMYFUNCTION("""COMPUTED_VALUE"""),1.0) -> 1 | G36: =IFERROR(__xludf.DUMMYFUNCTION("""COMPUTED_VALUE"""),120000.0) -> 120000 | H36: =IFERROR(__xludf.DUMMYFUNCTION("""COMPUTED_VALUE"""),120000.0) -> 120000 | L36: Seragam PDH Rompi | M36: =SUMIFS(H33:H76,E33:E76,L36) -> 0
C37: =IFERROR(__xludf.DUMMYFUNCTION("""COMPUTED_VALUE"""),"PT Anugerah Kasih Putera (Body and Paint)") -> PT Anugerah Kasih Putera (Body and Paint) | D37: =IFERROR(__xludf.DUMMYFUNCTION("""COMPUTED_VALUE"""),46133.0) -> 46133 | E37: =IFERROR(__xludf.DUMMYFUNCTION("""COMPUTED_VALUE"""),"Seragam Honda (Teknisi)") -> Seragam Honda (Teknisi) | F37: =IFERROR(__xludf.DUMMYFUNCTION("""COMPUTED_VALUE"""),1.0) -> 1 | G37: =IFERROR(__xludf.DUMMYFUNCTION("""COMPUTED_VALUE"""),130000.0) -> 130000 | H37: =IFERROR(__xludf.DUMMYFUNCTION("""COMPUTED_VALUE"""),130000.0) -> 130000
C38: =IFERROR(__xludf.DUMMYFUNCTION("""COMPUTED_VALUE"""),"PT Anugerah Kasih Putera (Body and Paint)") -> PT Anugerah Kasih Putera (Body and Paint) | D38: =IFERROR(__xludf.DUMMYFUNCTION("""COMPUTED_VALUE"""),46133.0) -> 46133 | E38: =IFERROR(__xludf.DUMMYFUNCTION("""COMPUTED_VALUE"""),"Seragam Honda (Teknisi)") -> Seragam Honda (Teknisi) | F38: =IFERROR(__xludf.DUMMYFUNCTION("""COMPUTED_VALUE"""),1.0) -> 1 | G38: =IFERROR(__xludf.DUMMYFUNCTION("""COMPUTED_VALUE"""),150000.0) -> 150000 | H38: =IFERROR(__xludf.DUMMYFUNCTION("""COMPUTED_VALUE"""),150000.0) -> 150000
C39: =IFERROR(__xludf.DUMMYFUNCTION("""COMPUTED_VALUE"""),"Ibu Chacha") -> Ibu Chacha | D39: =IFERROR(__xludf.DUMMYFUNCTION("""COMPUTED_VALUE"""),46133.0) -> 46133 | E39: =IFERROR(__xludf.DUMMYFUNCTION("""COMPUTED_VALUE"""),"Seragam Honda (Teknisi)") -> Seragam Honda (Teknisi) | F39: =IFERROR(__xludf.DUMMYFUNCTION("""COMPUTED_VALUE"""),1.0) -> 1 | G39: =IFERROR(__xludf.DUMMYFUNCTION("""COMPUTED_VALUE"""),110000.0) -> 110000 | H39: =IFERROR(__xludf.DUMMYFUNCTION("""COMPUTED_VALUE"""),110000.0) -> 110000 | K39: Product
C40: =IFERROR(__xludf.DUMMYFUNCTION("""COMPUTED_VALUE"""),"Ibu Chacha") -> Ibu Chacha | D40: =IFERROR(__xludf.DUMMYFUNCTION("""COMPUTED_VALUE"""),46133.0) -> 46133 | E40: =IFERROR(__xludf.DUMMYFUNCTION("""COMPUTED_VALUE"""),"Seragam Honda (Teknisi)") -> Seragam Honda (Teknisi) | F40: =IFERROR(__xludf.DUMMYFUNCTION("""COMPUTED_VALUE"""),1.0) -> 1 | G40: =IFERROR(__xludf.DUMMYFUNCTION("""COMPUTED_VALUE"""),150000.0) -> 150000 | H40: =IFERROR(__xludf.DUMMYFUNCTION("""COMPUTED_VALUE"""),150000.0) -> 150000 | K40: Seragam PDH Custom | L40: =SUMIFS(G2:G45,E2:E45,K40) -> 0
...

Sheet BULAN BERJALAN BANUA
A1: IITEM CODE | B1: INSTANSI | C1: CUSTOMER | D1: DATE | E1: PRODUCT | F1: QTY | G1: PRICE | H1: TOTAL PRICE | I1: KETERANGAN | J1: Column 10
A2: SMK NON TBSM | B2: Sekolah Kejuruan | C2: Pak Bayu (SMK Muhammadiyah Moyudan) | D2: 45827 | E2: Wearpack Yamaha | F2: 7 | G2: 200000 | I2: 0857 0122 4831
A3: SMK NON TBSM | B3: Sekolah Kejuruan | C3: Pak Bayu (SMK Muhammadiyah Moyudan) | D3: 45827 | E3: Wearpack Yamaha | F3: 2 | G3: 220000 | H3: =F3*G3 -> 440000 | I3: 0857 0122 4831
A4: SMK NON TBSM | B4: Sekolah Kejuruan | C4: Pak Bayu (SMK Muhammadiyah Moyudan) | D4: 45827 | E4: Wearpack Yamaha | F4: 1 | G4: 240000 | H4: =F4*G4 -> 240000 | I4: 0857 0122 4831
A5: TOYOTA | B5: PT. Kala Suba Indonesia | C5: Vicky | D5: 45831 | E5: Wearpack Toyota | F5: 20 | G5: 210000 | H5: =F5*G5 -> 4200000 | J5: sama
A6: YAMAHA | B6: Sekolah Kejuruan | C6: Pak Sigit (SMK Muhammadiyah 1 Moyudan) | D6: 45831 | E6: Wearpack Yamaha | F6: 10 | H6: 2070000 | J6: sama
A7: tolong lengkapi | B7: tolong lengkapi | C7: Surat Motor | D7: 45831 | E7: FLP Kerah Merah | F7: 10 | G7: 240000 | H7: =F7*G7 -> 2400000
A8: tolong lengkapi | B8: tolong lengkapi | C8: Surat Motor | D8: 45831 | E8: FLP Kerah Merah | F8: 2 | G8: 250000 | H8: =F8*G8 -> 500000
A9: SMK NON TBSM | B9: Sekolah Kejuruan | C9: Pak Ubay (SMKS Muhammadiyah Gunung Agung) | D9: 45839 | E9: Seragam DKV | F9: 50 | G9: 115000 | H9: =F9*G9 -> 5750000 | I9: 0853 5750 2112 | J9: sama
A10: SMK NON TBSM | B10: Sekolah Kejuruan | C10: Pak Ubay (SMKS Muhammadiyah Gunung Agung) | D10: 45839 | E10: Seragam DKV | F10: 2 | G10: 125000 | H10: =F10*G10 -> 250000 | I10: 0853 5750 2112 | J10: sama
A11: SMK NON TBSM | B11: Sekolah Kejuruan | C11: Pak Ubay (SMKS Muhammadiyah Gunung Agung) | D11: 45839 | E11: Seragam Pemasaran | F11: 57 | G11: 115000 | H11: =F11*G11 -> 6555000 | I11: 0853 5750 2112 | J11: sama
A12: SMK NON TBSM | B12: Sekolah Kejuruan | C12: Pak Ubay (SMKS Muhammadiyah Gunung Agung) | D12: 45839 | E12: Seragam Pemasaran | F12: 3 | G12: 125000 | H12: =F12*G12 -> 375000 | I12: 0853 5750 2112 | J12: sama
A13: SMK NON TBSM | B13: Sekolah Kejuruan | C13: Pak Ubay (SMKS Muhammadiyah Gunung Agung) | D13: 45839 | E13: Seragam Pemasaran | F13: 1 | G13: 135000 | H13: =F13*G13 -> 135000 | I13: 0853 5750 2112 | J13: sama
A14: SMK NON TBSM | B14: Sekolah Kejuruan | C14: Pak Ubay (SMKS Muhammadiyah Gunung Agung) | D14: 45839 | E14: Seragam Akuntansi | F14: 12 | G14: 115000 | H14: =F14*G14 -> 1380000 | I14: 0853 5750 2112 | J14: sama
A15: SMK NON TBSM | B15: Sekolah Kejuruan | C15: Pak Ubay (SMKS Muhammadiyah Gunung Agung) | D15: 45839 | E15: Seragam Olahraga | F15: 150 | G15: 107000 | H15: =F15*G15 -> 16050000 | I15: 0853 5750 2112 | J15: sama
A16: HONDA MOBIL | B16: PT. Tajimura Maju Bersama | C16: PT. Tajimura Maju Bersama | D16: 45839 | E16: Honda Mobil | F16: 10 | G16: 200000 | H16: =F16*G16 -> 2000000 | J16: sama
A17: TOYOTA | B17: Toyota | C17: Pak Windarto ( Bengkel Jaya Abadi) | D17: 45840 | E17: Wearpack Toyota | F17: 10 | G17: 190000 | H17: =F17*G17 -> 1900000 | J17: sama
A18: tolong lengkapi | B18: Honda | C18: =C20 -> PT. Tajimura Maju Bersama | D18: 45846 | E18: Honda Mobil | F18: 1 | G18: 200000 | H18: =F18*G18 -> 200000
A19: tolong lengkapi | B19: Honda | C19: Pak Sigit (SMK Muhammadiyah 1 Moyudan) | D19: 45846 | F19: 2 | G19: 25000 | H19: =F19*G19 -> 50000
A20: WULING | B20: PT. Tajimura Maju Bersama | C20: PT. Tajimura Maju Bersama | D20: 45840 | E20: Mekanik Wulling | F20: 1 | G20: 210000 | H20: =F20*G20 -> 210000 | J20: sama
A21: SMK NON TBSM | B21: Sekolah Kejuruan | C21: Pak Sigit (SMK Muhammadiyah 1 Moyudan) | D21: 45840 | E21: Mekanik Honda Motor 1 Set | F21: 2 | G21: 235000 | H21: =F21*G21 -> 470000 | J21: sama
A22: SMK NON TBSM | B22: Honda | C22: Pak Erwin ( Mandala Jaya Abadi) | D22: 45845 | E22: Wearpack Honda Custom | F22: 50 | G22: 120000 | H22: =F22*G22 -> 6000000 | J22: sama
A23: UMUM KOMUNITAS | B23: Sekolah Umum | C23: Ibu Isna ( orang tua murid) | D23: 45845 | E23: Seragam SMP | F23: 1 | G23: 173000 | H23: =F23*G23 -> 173000 | J23: sama
B24: PT. Tajimura Maju Bersama | C24: PT. Tajimura Maju Bersama | D24: 45847 | E24: Wearpack Honda Custom dan Topi | F24: 3 | H24: 250000 | J24: sama
B25: PT Tanaka | C25: PT Tanaka | D25: 45848 | E25: Wearpack Custom | F25: 12 | G25: 225000 | H25: =F25*G25 -> 2700000 | J25: sama
A26: UMUM KOMUNITAS | B26: Sekolah Umum | D26: 45852 | E26: Seragam SD Set | F26: 1 | G26: 99000 | H26: =F26*G26 -> 99000 | J26: sama
A27: YAMAHA | D27: 45852 | E27: Wearpack Yamaha | F27: 1 | G27: 230000 | H27: =F27*G27 -> 230000 | J27: sama
A28: UMUM KOMUNITAS | B28: Sekolah Kejuruan | C28: Pak Guntarto | E28: Seragam TBSM | F28: 19 | H28: 3720000 | J28: sama
A29: UMUM KOMUNITAS | B29: Sekolah Kejuruan | C29: Pak Rahmat | E29: Seragam TBSM | F29: 30 | H29: 6780000 | J29: sama
A30: UMUM KOMUNITAS | B30: Universitas | C30: Pak Triyanto (Tata Busana UNY) | D30: 45855 | E30: Seragam PDH | F30: 8 | G30: 155000 | H30: =F30*G30 -> 1240000 | J30: sama
A31: UMUM KOMUNITAS | B31: Universitas | C31: Pak Triyanto (Tata Busana UNY) | D31: 45855 | E31: Seragam PDH | F31: 3 | G31: 165000 | H31: =F31*G31 -> 495000 | J31: sama
A32: UMUM KOMUNITAS | B32: Universitas | C32: Pak Triyanto (Tata Busana UNY) | D32: 45855 | E32: Seragam PDH | F32: 2 | G32: 175000 | H32: =F32*G32 -> 350000 | J32: sama
A33: tolong lengkapi | B33: Yamaha | C33: Fortuna Yamaha Tumbang Titi | D33: 45870 | E33: Seragam | F33: 6 | G33: 145000 | H33: =F33*G33 -> 870000
A34: UMUM KOMUNITAS | B34: Sekolah Kejuruan | C34: Pak Supoyo (SMK Muhammadiyah 3 Waleri) | D34: 45873 | E34: Seragam TBSM + Seragam Guru | F34: 111 | H34: 18870000 | J34: sama
A35: tolong lengkapi | B35: tolong lengkapi | C35: Pak Edi (Sultan Motor) | D35: 45874 | E35: FLP Cowok dan Cewek | F35: 10 | G35: 130000 | H35: =F35*G35 -> 1300000
A36: UMUM KOMUNITAS | B36: Lampung Independt Vespa | C36: Bu Yeni Lestari | D36: 45873 | E36: Seragam Komunitas Vespa | F36: 4 | G36: 235000 | H36: =F36*G36 -> 940000 | J36: sama
A37: tolong lengkapi | B37: Toyota | C37: PT. Kala Suba Indonesia | D37: 45875 | E37: Wearpack Toyota | F37: 20 | G37: 210000 | H37: =F37*G37 -> 4200000
A38: UMUM KOMUNITAS | B38: Sekolah Kejuruan | C38: Rinto Dwi Endratmako (SMKN 1 Entikong) | D38: 45877 | E38: Seragam SMK | F38: 52 | G38: 210000 | H38: =F38*G38 -> 10920000 | J38: sama
A39: UMUM KOMUNITAS | B39: Sekolah Kejuruan | C39: Rinto Dwi Endratmako (SMKN 1 Entikong) | D39: 45877 | E39: Seragam SMK | F39: 53 | G39: 225000 | H39: =F39*G39 -> 11925000 | J39: sama
A40: UMUM KOMUNITAS | B40: Sekolah Kejuruan | C40: Rinto Dwi Endratmako (SMKN 1 Entikong) | D40: 45877 | E40: Seragam SMK | F40: 5 | G40: 125000 | H40: =F40*G40 -> 625000 | J40: sama
...

Sheet Ach MTD NOVEMBER 2025
B2: Department | C2: Marketing
B3: PIC | C3: Aji
B4: Bulan | C4: Januari
B5: Target Bulanan | C5: 100000000
B6: Target Harian | C6: =C5/30 -> 3333333.3
B7: TGL | C7: AJI | K7: OKTOBER | L7: NOVEMBER
C8: BANUA 2025
C9: TARGET | D9: ACTUAL | E9: OKTOBER
B10: 1 | C10: =$C$6 -> 3333333.3 | D10: =SUMIF('BULAN BERJALAN BANUA'!D:D,$L10,'BULAN BERJALAN BANUA'!H:H) -> 130000 | E10: =SUMIF('BULAN BERJALAN BANUA'!$D:$D,$K10,'BULAN BERJALAN BANUA'!$H:$H) -> 0 | K10: {=SEQUENCE( DAY(EOMONTH(DATE(2025, MATCH(K$7, {"JANUARI";"FEBRUARI";"MARET";"APRIL";"MEI";"JUNI";"JULI";"AGUSTUS";"SEPTEMBER";"OKTOBER";"NOVEMBER";"DESEMBER"}, 0), 1), 0)), 1, DATE(2025, MATCH(K$1, {"JANUARI";"FEBRUARI";"MARET";"APRIL";"MEI";"JUNI";"JULI";"AGUSTUS";"SEPTEMBER";"OKTOBER";"NOVEMBER";"DESEMBER"}, 0), 1), 1 )} -> #N/A | L10: 45962
B11: 2 | C11: =$C$6 -> 3333333.3 | D11: =SUMIF('BULAN BERJALAN BANUA'!D:D,$L11,'BULAN BERJALAN BANUA'!H:H) -> 0 | E11: =SUMIF('BULAN BERJALAN BANUA'!$D:$D,$K11,'BULAN BERJALAN BANUA'!$H:$H) -> 0 | K11: 45932 | L11: 45963
B12: 3 | C12: =$C$6 -> 3333333.3 | D12: =SUMIF('BULAN BERJALAN BANUA'!D:D,$L12,'BULAN BERJALAN BANUA'!H:H) -> 0 | E12: =SUMIF('BULAN BERJALAN BANUA'!$D:$D,$K12,'BULAN BERJALAN BANUA'!$H:$H) -> 0 | K12: 45933 | L12: 45964
B13: 4 | C13: =$C$6 -> 3333333.3 | D13: =SUMIF('BULAN BERJALAN BANUA'!D:D,$L13,'BULAN BERJALAN BANUA'!H:H) -> 200000 | E13: =SUMIF('BULAN BERJALAN BANUA'!$D:$D,$K13,'BULAN BERJALAN BANUA'!$H:$H) -> 0 | K13: 45934 | L13: 45965
B14: 5 | C14: =$C$6 -> 3333333.3 | D14: =SUMIF('BULAN BERJALAN BANUA'!D:D,$L14,'BULAN BERJALAN BANUA'!H:H) -> 0 | E14: =SUMIF('BULAN BERJALAN BANUA'!$D:$D,$K14,'BULAN BERJALAN BANUA'!$H:$H) -> 0 | K14: 45935 | L14: 45966
B15: 6 | C15: =$C$6 -> 3333333.3 | D15: =SUMIF('BULAN BERJALAN BANUA'!D:D,$L15,'BULAN BERJALAN BANUA'!H:H) -> 0 | E15: =SUMIF('BULAN BERJALAN BANUA'!$D:$D,$K15,'BULAN BERJALAN BANUA'!$H:$H) -> 2580000 | K15: 45936 | L15: 45967
B16: 7 | C16: =$C$6 -> 3333333.3 | D16: =SUMIF('BULAN BERJALAN BANUA'!D:D,$L16,'BULAN BERJALAN BANUA'!H:H) -> 470000 | E16: =SUMIF('BULAN BERJALAN BANUA'!$D:$D,$K16,'BULAN BERJALAN BANUA'!$H:$H) -> 0 | K16: 45937 | L16: 45968
B17: 8 | C17: =$C$6 -> 3333333.3 | D17: =SUMIF('BULAN BERJALAN BANUA'!D:D,$L17,'BULAN BERJALAN BANUA'!H:H) -> 0 | E17: =SUMIF('BULAN BERJALAN BANUA'!$D:$D,$K17,'BULAN BERJALAN BANUA'!$H:$H) -> 3300000 | K17: 45938 | L17: 45969
B18: 9 | C18: =$C$6 -> 3333333.3 | D18: =SUMIF('BULAN BERJALAN BANUA'!D:D,$L18,'BULAN BERJALAN BANUA'!H:H) -> 0 | E18: =SUMIF('BULAN BERJALAN BANUA'!$D:$D,$K18,'BULAN BERJALAN BANUA'!$H:$H) -> 10420000 | K18: 45939 | L18: 45970
B19: 10 | C19: =$C$6 -> 3333333.3 | D19: =SUMIF('BULAN BERJALAN BANUA'!D:D,$L19,'BULAN BERJALAN BANUA'!H:H) -> 3145000 | E19: =SUMIF('BULAN BERJALAN BANUA'!$D:$D,$K19,'BULAN BERJALAN BANUA'!$H:$H) -> 0 | K19: 45940 | L19: 45971
B20: 11 | C20: =$C$6 -> 3333333.3 | D20: =SUMIF('BULAN BERJALAN BANUA'!D:D,$L20,'BULAN BERJALAN BANUA'!H:H) -> 0 | E20: =SUMIF('BULAN BERJALAN BANUA'!$D:$D,$K20,'BULAN BERJALAN BANUA'!$H:$H) -> 60000 | K20: 45941 | L20: 45972
B21: 12 | C21: =$C$6 -> 3333333.3 | D21: =SUMIF('BULAN BERJALAN BANUA'!D:D,$L21,'BULAN BERJALAN BANUA'!H:H) -> 11535000 | E21: =SUMIF('BULAN BERJALAN BANUA'!$D:$D,$K21,'BULAN BERJALAN BANUA'!$H:$H) -> 0 | K21: 45942 | L21: 45973
B22: 13 | C22: =$C$6 -> 3333333.3 | D22: =SUMIF('BULAN BERJALAN BANUA'!D:D,$L22,'BULAN BERJALAN BANUA'!H:H) -> 0 | E22: =SUMIF('BULAN BERJALAN BANUA'!$D:$D,$K22,'BULAN BERJALAN BANUA'!$H:$H) -> 4248000 | K22: 45943 | L22: 45974
... B39: 30 | C39: =$C$6 -> 3333333.3 | D39: =SUMIF('BULAN BERJALAN BANUA'!D:D,$L39,'BULAN BERJALAN BANUA'!H:H) -> 0 | E39: =SUMIF('BULAN BERJALAN BANUA'!$D:$D,$K39,'BULAN BERJALAN BANUA'!$H:$H) -> 0 | K39: 45960 | L39: 45991
B40: 31 | E40: =SUMIF('BULAN BERJALAN BANUA'!$D:$D,$K40,'BULAN BERJALAN BANUA'!$H:$H) -> 2275000 | K40: 45961
B43: TOTAL | C43: =SUM(C10:C40) -> 100000000 | D43: =SUM(D10:D41) -> 26910000 | E43: =SUM(E10:E41) -> 62902000
C45: Target | E45: =C43 -> 100000000
C46: Actual | E46: =D43 -> 26910000
C47: Bulan Lalu | E47: =E43 -> 62902000
C48: Achivement By Target | E48: =E46/E45 -> 0.2691
C49: Achivement By Bulan Lalu | E49: =E46/E47 -> 0.42780834

Sheet BULAN BERJALAN TANAKA
A1: IITEM CODE | B1: INSTANSI | C1: CUSTOMER | D1: DATE | E1: PRODUCT | F1: QTY | G1: PRICE | H1: TOTAL PRICE | I1: KETERANGAN | J1: Column 10
H2: =F2*G2 -> 0
H3: =F3*G3 -> 0
H4: =F4*G4 -> 0
H5: =F5*G5 -> 0
H6: =F6*G6 -> 0
H7: =F7*G7 -> 0
H8: =F8*G8 -> 0
H9: =F9*G9 -> 0
H10: =F10*G10 -> 0
C11: Ardi | D11: 46011 | E11: Atasan Custom Toyota | F11: 6 | G11: 172000 | H11: =F11*G11 -> 1032000
C12: Pak Agus | D12: 46004 | E12: Satu Set Honda Mobil | F12: 10 | G12: 265000 | H12: =F12*G12 -> 2650000
C13: =C14 -> PT Atmaja Dharma Artha | D13: =D14 -> 46003 | E13: =E14 -> ATASAN SERAGAM SAFETY + REFKLEKTOR | F13: 6 | G13: 138000 | H13: =F13*G13 -> 828000
C14: PT Atmaja Dharma Artha | D14: 46003 | E14: ATASAN SERAGAM SAFETY + REFKLEKTOR | F14: 56 | G14: 128000 | H14: =F14*G14 -> 7168000
C15: PKM Corner UII | D15: 45942 | E15: JAKET BOMBER | F15: 1 | G15: 200000 | H15: =F15*G15 -> 200000
C16: PKM Corner UII | D16: 45943 | E16: JAKET BOMBER | F16: 1 | G16: 100000 | H16: =F16*G16 -> 100000
C17: PKM Corner UII | D17: 45944 | E17: JAKET BOMBER | F17: 10 | G17: 190000 | H17: =F17*G17 -> 1900000
C18: PT atmaja dharma artha | D18: 45969 | E18: Kemeja dan Celanan Safety | F18: 1 | G18: 300000 | H18: =F18*G18 -> 300000
C19: Ahass Makmur Ambarawa | D19: 45964 | E19: Apron | F19: 5 | G19: 30000 | H19: =F19*G19 -> 150000
C20: Ahass Makmur Ambarawa | D20: 45965 | E20: Celana Mekanik Honda | F20: 2 | G20: 130000 | H20: =F20*G20 -> 260000
C21: Ahass Makmur Ambarawa | D21: 45966 | E21: Celana Mekanik Honda | F21: 2 | G21: 120000 | H21: =F21*G21 -> 240000
A22: UMUM KOMUNITAS | C22: Erviq | D22: 46029 | E22: celana spbu operator | F22: 6 | G22: 250000 | H22: =F22*G22 -> 1500000
A23: UMUM KOMUNITAS | C23: Erviq | D23: 46029 | E23: celana spbu operator | F23: 9 | G23: 260000 | H23: =F23*G23 -> 2340000
A24: HONDA MOTOR | C24: Pak Samsun | D24: 46034 | E24: Topi dan Apron | F24: 300 | G24: 21000 | H24: =F24*G24 -> 6300000
A25: HONDA MOTOR | C25: pak Umar (Ahass Paru Jaya Surabaya) | D25: 46036 | E25: FLP cowo kerah merah | F25: 1 | G25: 132000 | H25: =F25*G25 -> 132000
A26: UMUM COMPANY | B26: PT HALUAN DINAMIKA UTAMA | D26: 46041 | E26: Kemaja mekanik custom. | F26: 15 | G26: 130000 | H26: =F26*G26 -> 1950000
A27: HONDA MOTOR | C27: Muchamad syamsul maarif | D27: 46055 | E27: Kemeja FLP | F27: 2 | H27: 224262
A28: YAMAHA | C28: Atang | D28: 46056 | E28: Wearpack Yamaha Polos | F28: 4 | G28: 210000 | H28: =F28*G28 -> 840000 | I28: =sum(H27:H31) -> 12804262
A29: YAMAHA | C29: Atang | D29: 46056 | E29: Wearpack Yamaha Polos | F29: 2 | G29: 220000 | H29: =F29*G29 -> 440000
A30: UMUM COMPANY | B30: PT Atmaja Dharma Artha | C30: Roberty | D30: 46060 | E30: Polo safety + reflektor | F30: 70 | G30: 140000 | H30: =F30*G30 -> 9800000
A31: UMUM COMPANY | B31: PT Atmaja Dharma Artha | C31: Roberty | D31: 46060 | E31: Polo safety + reflektor | F31: 10 | G31: 150000 | H31: =F31*G31 -> 1500000
B32: Ahass Kurnia Motor Boyolali | C32: Pak Faisal | D32: 46086 | E32: Topi dan Apron | F32: 20 | G32: 23000 | H32: =F32*G32 -> 460000
H33: =F33*G33 -> 0
H34: =F34*G34 -> 0
H35: =F35*G35 -> 0
H36: =F36*G36 -> 0
H37: =F37*G37 -> 0
H38: =F38*G38 -> 0
H39: =F39*G39 -> 0
H40: =F40*G40 -> 0
...

Sheet LAPORAN HARIAN
C1: PENDAPATAN HARIAN NOVEMBER 2025
C2: TANGGAL | D2: 46030 | E2: Bulan Sblmnya
D3: 46023 | E3: Bulan Berjalan
C7: no | D7: Kategori | E7: tanggal | F7: Pendapatan | G7: Achivment
C8: 1 | D8: HONDA MOTOR | E8: =$D$2 -> 46030 | F8: =SUMIFS( 'BULAN BERJALAN BANUA'!H:H, 'BULAN BERJALAN BANUA'!A:A, $D$8, 'BULAN BERJALAN BANUA'!D:D, ">="&EOMONTH(E8,-1)+1, 'BULAN BERJALAN BANUA'!D:D, "<="&E8) -> 900000 | G8: =IF(F8=0, 0, F9/F8) -> 1
E9: =$D$3 -> 46023 | F9: =SUMIFS( 'BULAN BERJALAN BANUA'!H:H, 'BULAN BERJALAN BANUA'!A:A, $D$8, 'BULAN BERJALAN BANUA'!D:D, ">="&EOMONTH(E9,-1)+1, 'BULAN BERJALAN BANUA'!D:D, "<="&E9) -> 900000
C10: 2 | D10: WULING | E10: =$D$2 -> 46030 | F10: =SUMIFS( 'BULAN BERJALAN BANUA'!H:H, 'BULAN BERJALAN BANUA'!A:A, $D$10, 'BULAN BERJALAN BANUA'!D:D, ">="&EOMONTH(E10,-1)+1, 'BULAN BERJALAN BANUA'!D:D, "<="&E10) -> 0 | G10: =IF(F10=0, 0, F11/F10) -> 0
E11: =$D$3 -> 46023 | F11: =SUMIFS( 'BULAN BERJALAN BANUA'!H:H, 'BULAN BERJALAN BANUA'!A:A, $D$10, 'BULAN BERJALAN BANUA'!D:D, ">="&EOMONTH(E11,-1)+1, 'BULAN BERJALAN BANUA'!D:D, "<="&E11) -> 0
C12: 3 | D12: HONDA MOBIL | E12: =$D$2 -> 46030 | F12: =SUMIFS( 'BULAN BERJALAN BANUA'!H:H, 'BULAN BERJALAN BANUA'!A:A, $D$12, 'BULAN BERJALAN BANUA'!D:D, ">="&EOMONTH(E12,-1)+1, 'BULAN BERJALAN BANUA'!D:D, "<="&E12) -> 0 | G12: =IF(F12=0, 0, F13/F12) -> 0
E13: =$D$3 -> 46023 | F13: =SUMIFS( 'BULAN BERJALAN BANUA'!H:H, 'BULAN BERJALAN BANUA'!A:A, $D$12, 'BULAN BERJALAN BANUA'!D:D, ">="&EOMONTH(E13,-1)+1, 'BULAN BERJALAN BANUA'!D:D, "<="&E13) -> 0
C14: 4 | D14: SUZUKI | E14: =$D$2 -> 46030 | F14: =SUMIFS( 'BULAN BERJALAN BANUA'!H:H, 'BULAN BERJALAN BANUA'!A:A, $D$14, 'BULAN BERJALAN BANUA'!D:D, ">="&EOMONTH(E14,-1)+1, 'BULAN BERJALAN BANUA'!D:D, "<="&E14) -> 0 | G14: =IF(F14=0, 0, F15/F14) -> 0
E15: =$D$3 -> 46023 | F15: =SUMIFS( 'BULAN BERJALAN BANUA'!H:H, 'BULAN BERJALAN BANUA'!A:A, $D$14, 'BULAN BERJALAN BANUA'!D:D, ">="&EOMONTH(E15,-1)+1, 'BULAN BERJALAN BANUA'!D:D, "<="&E15) -> 0
C16: 5 | D16: DAIHATSU | E16: =$D$2 -> 46030 | F16: =SUMIFS( 'BULAN BERJALAN BANUA'!H:H, 'BULAN BERJALAN BANUA'!A:A, $D$16, 'BULAN BERJALAN BANUA'!D:D, ">="&EOMONTH(E16,-1)+1, 'BULAN BERJALAN BANUA'!D:D, "<="&E16) -> 0 | G16: =IF(F16=0, 0, F17/F16) -> 0
E17: =$D$3 -> 46023 | F17: =SUMIFS( 'BULAN BERJALAN BANUA'!H:H, 'BULAN BERJALAN BANUA'!A:A, $D$16, 'BULAN BERJALAN BANUA'!D:D, ">="&EOMONTH(E17,-1)+1, 'BULAN BERJALAN BANUA'!D:D, "<="&E17) -> 0
C18: 6 | D18: MITSUBISHI | E18: =$D$2 -> 46030 | F18: =SUMIFS( 'BULAN BERJALAN BANUA'!H:H, 'BULAN BERJALAN BANUA'!A:A, $D$18, 'BULAN BERJALAN BANUA'!D:D, ">="&EOMONTH(E18,-1)+1, 'BULAN BERJALAN BANUA'!D:D, "<="&E18) -> 0 | G18: =IF(F18=0, 0, F19/F18) -> 0
E19: =$D$3 -> 46023 | F19: =SUMIFS( 'BULAN BERJALAN BANUA'!H:H, 'BULAN BERJALAN BANUA'!A:A, $D$18, 'BULAN BERJALAN BANUA'!D:D, ">="&EOMONTH(E19,-1)+1, 'BULAN BERJALAN BANUA'!D:D, "<="&E19) -> 0
C20: 7 | D20: MAZDA | E20: =$D$2 -> 46030 | F20: =SUMIFS( 'BULAN BERJALAN BANUA'!H:H, 'BULAN BERJALAN BANUA'!A:A, $D$20, 'BULAN BERJALAN BANUA'!D:D, ">="&EOMONTH(E20,-1)+1, 'BULAN BERJALAN BANUA'!D:D, "<="&E20) -> 0 | G20: =IF(F20=0, 0, F21/F20) -> 0
E21: =$D$3 -> 46023 | F21: =SUMIFS( 'BULAN BERJALAN BANUA'!H:H, 'BULAN BERJALAN BANUA'!A:A, $D$20, 'BULAN BERJALAN BANUA'!D:D, ">="&EOMONTH(E21,-1)+1, 'BULAN BERJALAN BANUA'!D:D, "<="&E21) -> 0
C22: 8 | D22: TOYOTA | E22: =$D$2 -> 46030 | F22: =SUMIFS( 'BULAN BERJALAN BANUA'!H:H, 'BULAN BERJALAN BANUA'!A:A, $D$22, 'BULAN BERJALAN BANUA'!D:D, ">="&EOMONTH(E22,-1)+1, 'BULAN BERJALAN BANUA'!D:D, "<="&E22) -> 1900000 | G22: =IF(F22=0, 0, F23/F22) -> 0
E23: =$D$3 -> 46023 | F23: =SUMIFS( 'BULAN BERJALAN BANUA'!H:H, 'BULAN BERJALAN BANUA'!A:A, $D$22, 'BULAN BERJALAN BANUA'!D:D, ">="&EOMONTH(E23,-1)+1, 'BULAN BERJALAN BANUA'!D:D, "<="&E23) -> 0
C24: 9 | D24: YAMAHA | E24: =$D$2 -> 46030 | F24: =SUMIFS( 'BULAN BERJALAN BANUA'!H:H, 'BULAN BERJALAN BANUA'!A:A, $D$24, 'BULAN BERJALAN BANUA'!D:D, ">="&EOMONTH(E24,-1)+1, 'BULAN BERJALAN BANUA'!D:D, "<="&E24) -> 0 | G24: =IF(F24=0, 0, F25/F24) -> 0
E25: =$D$3 -> 46023 | F25: =SUMIFS( 'BULAN BERJALAN BANUA'!H:H, 'BULAN BERJALAN BANUA'!A:A, $D$24, 'BULAN BERJALAN BANUA'!D:D, ">="&EOMONTH(E25,-1)+1, 'BULAN BERJALAN BANUA'!D:D, "<="&E25) -> 0
C26: 10 | D26: SMK TBSM HONDA | E26: =$D$2 -> 46030 | F26: =SUMIFS( 'BULAN BERJALAN BANUA'!H:H, 'BULAN BERJALAN BANUA'!A:A, $D$26, 'BULAN BERJALAN BANUA'!D:D, ">="&EOMONTH(E26,-1)+1, 'BULAN BERJALAN BANUA'!D:D, "<="&E26) -> 0 | G26: =IF(F26=0, 0, F27/F26) -> 0
E27: =$D$3 -> 46023 | F27: =SUMIFS( 'BULAN BERJALAN BANUA'!H:H, 'BULAN BERJALAN BANUA'!A:A, $D$26, 'BULAN BERJALAN BANUA'!D:D, ">="&EOMONTH(E27,-1)+1, 'BULAN BERJALAN BANUA'!D:D, "<="&E27) -> 0
C28: 11 | D28: SMK NON TBSM | E28: =$D$2 -> 46030 | F28: =SUMIFS( 'BULAN BERJALAN BANUA'!H:H, 'BULAN BERJALAN BANUA'!A:A, $D$28, 'BULAN BERJALAN BANUA'!D:D, ">="&EOMONTH(E28,-1)+1, 'BULAN BERJALAN BANUA'!D:D, "<="&E28) -> 2340000 | G28: =IF(F28=0, 0, F29/F28) -> 0
E29: =$D$3 -> 46023 | F29: =SUMIFS( 'BULAN BERJALAN BANUA'!H:H, 'BULAN BERJALAN BANUA'!A:A, $D$28, 'BULAN BERJALAN BANUA'!D:D, ">="&EOMONTH(E29,-1)+1, 'BULAN BERJALAN BANUA'!D:D, "<="&E29) -> 0
C30: 12 | D30: TK | E30: =$D$2 -> 46030 | F30: =SUMIFS( 'BULAN BERJALAN BANUA'!H:H, 'BULAN BERJALAN BANUA'!A:A, $D$30, 'BULAN BERJALAN BANUA'!D:D, ">="&EOMONTH(E30,-1)+1, 'BULAN BERJALAN BANUA'!D:D, "<="&E30) -> 0 | G30: =IF(F30=0, 0, F31/F30) -> 0
E31: =$D$3 -> 46023 | F31: =SUMIFS( 'BULAN BERJALAN BANUA'!H:H, 'BULAN BERJALAN BANUA'!A:A, $D$30, 'BULAN BERJALAN BANUA'!D:D, ">="&EOMONTH(E31,-1)+1, 'BULAN BERJALAN BANUA'!D:D, "<="&E31) -> 0
C32: 10 | D32: UMUM KAMPUS | E32: =$D$2 -> 46030 | F32: =SUMIFS( 'BULAN BERJALAN BANUA'!H:H, 'BULAN BERJALAN BANUA'!A:A, $D$32, 'BULAN BERJALAN BANUA'!D:D, ">="&EOMONTH(E32,-1)+1, 'BULAN BERJALAN BANUA'!D:D, "<="&E32) -> 0 | G32: =IF(F32=0, 0, F33/F32) -> 0
E33: =$D$3 -> 46023 | F33: =SUMIFS( 'BULAN BERJALAN BANUA'!H:H, 'BULAN BERJALAN BANUA'!A:A, $D$32, 'BULAN BERJALAN BANUA'!D:D, ">="&EOMONTH(E33,-1)+1, 'BULAN BERJALAN BANUA'!D:D, "<="&E33) -> 0
C34: 11 | D34: UMUM COMPANY | E34: =$D$2 -> 46030 | F34: =SUMIFS( 'BULAN BERJALAN BANUA'!H:H, 'BULAN BERJALAN BANUA'!A:A, $D$34, 'BULAN BERJALAN BANUA'!D:D, ">="&EOMONTH(E34,-1)+1, 'BULAN BERJALAN BANUA'!D:D, "<="&E34) -> 0 | G34: =IF(F34=0, 0, F35/F34) -> 0
E35: =$D$3 -> 46023 | F35: =SUMIFS( 'BULAN BERJALAN BANUA'!H:H, 'BULAN BERJALAN BANUA'!A:A, $D$34, 'BULAN BERJALAN BANUA'!D:D, ">="&EOMONTH(E35,-1)+1, 'BULAN BERJALAN BANUA'!D:D, "<="&E35) -> 0
C36: 12 | D36: UMUM KOMUNITAS | E36: =$D$2 -> 46030 | F36: =SUMIFS( 'BULAN BERJALAN BANUA'!H:H, 'BULAN BERJALAN BANUA'!A:A, $D$36, 'BULAN BERJALAN BANUA'!D:D, ">="&EOMONTH(E36,-1)+1, 'BULAN BERJALAN BANUA'!D:D, "<="&E36) -> 0 | G36: =IF(F36=0, 0, F37/F36) -> 0
E37: =$D$3 -> 46023 | F37: =SUMIFS( 'BULAN BERJALAN BANUA'!H:H, 'BULAN BERJALAN BANUA'!A:A, $D$36, 'BULAN BERJALAN BANUA'!D:D, ">="&EOMONTH(E37,-1)+1, 'BULAN BERJALAN BANUA'!D:D, "<="&E37) -> 0
C38: 13 | D38: TOTAL | E38: =$D$2 -> 46030 | F38: =F8+F10+F12+F14+F16+F18+F20+F22+F24+F26+F28+F30+F32+F34+F36 -> 5140000 | G38: =IF(F38=0, 0, F39/F38) -> 0.17509728
E39: =$D$3 -> 46023 | F39: =F9+F11+F13+F15+F17+F19+F21+F23+F25+F27+F29+F31+F33+F35+F37 -> 900000

Sheet LAPORAN BULANAN
C1: PENDAPATAN BULANAN [PERBANDINGAN BULAN DAN TAHUNNYA]
E2: BULAN | F2: 46054 | G2: Bulan
F3: 46054 | G3: Bulan Berjalan
C5: no | D5: Kategori | E5: tanggal | F5: Pendapatan | G5: Achivment
